Workbook

Sheet Payroll 
A4: Sum of TOTAL | B4: Payroll
A5: Location | B5: Agro | C5: Aroor | D5: Breads | E5: Green | F5: Hosur | G5: Kalamassery | H5: Mumbai | I5: YRFM | J5: Grand Total
A6: Agro | B6: 452982.71 | F6: 36808.631 | I6: 80949.322 | J6: 570740.66
A7: Ahmedabad | E7: 266366.68 | J7: 266366.68
A8: Aroor | C8: 687464.74 | G8: 13121.73 | I8: 25691.5 | J8: 726277.97
A9: Breads | B9: 56268.999 | C9: 46571.5 | D9: 539270.31 | F9: 147792.32 | I9: 85646.648 | J9: 875549.78
A10: Corporate | B10: 705912.15 | C10: 497953.5 | D10: 612679.67 | F10: 713622.04 | G10: 1850154.5 | H10: 86872.668 | I10: 1697414.8 | J10: 6164609.3
A11: Gardenia | B11: 17758.765 | G11: 33571.5 | J11: 51330.265
A12: Hosur | B12: 9128.16 | D12: 46831.5 | F12: 1225839.8 | G12: 61886.8 | I12: 50709.97 | J12: 1394396.3
A13: Indore | E13: 195907.85 | I13: 72643 | J13: 268550.85
A14: Kalamassery | B14: 19070.989 | G14: 807463.99 | I14: 57593 | J14: 884127.98
A15: Mumbai | G15: 123585.35 | H15: 559053.49 | I15: 21603.2 | J15: 704242.04
A16: Organic | B16: 13811.793 | E16: 665947.74 | I16: 71852.703 | J16: 751612.24
A17: Outsourcing | B17: 9128.16 | D17: 10269.18 | F17: 184271.45 | I17: 15403.77 | J17: 219072.56
A18: YRFM | B18: 81102.823 | D18: 91290.921 | I18: 1520051.8 | J18: 1692445.5
A19: Grand Total | B19: 1365164.5 | C19: 1231989.7 | D19: 1300341.6 | E19: 1128222.3 | F19: 2308334.3 | G19: 2889783.9 | H19: 645926.16 | I19: 3699559.6 | J19: 14569322
A22: Sum of TOTAL | B22: Payroll
A23: Division | B23: AGRO | C23: AROOR | D23: Bread | E23: Hosur | F23: KALAMASSERY | G23: Mumbai | H23: YRFM | I23: Grand Total
A24: Agro Sales | B24: 149144.44 | H24: 16843.65 | I24: 165988.09
A25: Andhrapradesh | E25: 218450.4 | I25: 218450.4
A26: Bulk | H26: 274865.48 | I26: 274865.48
A27: Cake Plus | B27: 25546.202 | C27: 74158.548 | D27: 17930.656 | F27: 66322.492 | I27: 183957.9
A28: CPS 1 | B28: 18222.299 | H28: 323229.19 | I28: 341451.49
A29: CPS Star | B29: 502692.72 | C29: 49687.69 | D29: 17703.822 | F29: 14036.375 | H29: 535759.33 | I29: 1119879.9
A30: Delhi | G30: 24303.6 | I30: 24303.6
A31: Gujarat | G31: 90249.604 | I31: 90249.604
A32: Karnataka | E32: 307015.16 | H32: 303148.35 | I32: 610163.51
A33: Mumbai | B33: 18416.728 | G33: 345407.15 | I33: 363823.88
A34: North Kerala - Breads | B34: 16418.432 | D34: 117178.4 | H34: 15799.344 | I34: 149396.17
A35: North Kerala - Cakes | B35: 14676.434 | D35: 16990.917 | F35: 48347.501 | H35: 39261.5 | I35: 119276.35
A36: Premix | B36: 60041.5 | I36: 60041.5
A37: South Kerala - Breads | C37: 87757.718 | F37: 45681.5 | H37: 47341.886 | I37: 180781.1
A38: South Kerala - Cakes | C38: 37891.5 | F38: 140102.78 | I38: 177994.28
A39: Tamil Nadu | D39: 127241.5 | E39: 48660.6 | H39: 697728.4 | I39: 873630.5
A40: Grand Total | B40: 805158.76 | C40: 249495.46 | D40: 297045.29 | E40: 574126.15 | F40: 314490.65 | G40: 459960.36 | H40: 2253977.1 | I40: 4954253.8
A44: Sum of TOTAL | B44: Payroll
A45: Division | B45: Agro | E45: Hosur | G45: Mumbai | H45: YRFM | I45: Grand Total
A46: Agro Sales | B46: 30131.9 | I46: 30131.9
A47: Bulk | B47: 26242.407 | H47: 192984.28 | I47: 219226.68
A48: CPS 1 | B48: 13048.214 | I48: 13048.214
...

Sheet Sheet1
A1: Sl.No. | B1: SAP NO | C1: Name | D1: Designation | E1: DOJ | F1: Band | G1: Gross Salary | H1: Salary | I1: New Division | J1: Department | K1: Payroll | L1: ESI | M1: PF | N1: Total
A2: 1 | B2: 9 | C2: A Shalu | D2: =VLOOKUP(B2,[2]sales!$B$2:$D$183,3,0) -> Territory Sales Manager | E2: 01.01.1993 | F2: P3 | G2: =VLOOKUP(B2,[9]Staff!B$7:H$245,7,0) -> 45090 | H2: =VLOOKUP(B2,[9]Staff!B$7:P$245,15,0) -> 45090 | I2: =VLOOKUP(B2,[2]sales!$B$2:$G$183,6,0) -> Bulk | J2: Bulk | K2: YRFM | L2: =IF(H2>23335,0,(H2*90%*4.75%)) -> 0 | M2: =IF(H2*60%*12%>1800,1974,(H2*60%*13.16%)) -> 1974 | N2: =H2+L2+M2 -> 47064
A3: 2 | B3: 27 | C3: M R Rajesh Kumar | D3: =VLOOKUP(B3,[2]sales!$B$2:$D$183,3,0) -> Sales Manager | E3: 01.11.1997 | F3: M2 | G3: =VLOOKUP(B3,[9]Staff!B$7:H$245,7,0) -> 66250 | H3: =VLOOKUP(B3,[9]Staff!B$7:P$245,15,0) -> 66250 | I3: =VLOOKUP(B3,[2]sales!$B$2:$G$183,6,0) -> Bulk | J3: Bulk | K3: YRFM | L3: =IF(H3>23335,0,(H3*90%*4.75%)) -> 0 | M3: =IF(H3*60%*12%>1800,1974,(H3*60%*13.16%)) -> 1974 | N3: =H3+L3+M3 -> 68224
A4: 3 | B4: 1667 | C4: Biby Boban | D4: =VLOOKUP(B4,[2]sales!$B$2:$D$183,3,0) -> Territory Sales Manager | E4: 01.10.2010 | F4: M1 | G4: =VLOOKUP(B4,[9]Staff!B$7:H$245,7,0) -> 42090 | H4: =VLOOKUP(B4,[9]Staff!B$7:P$245,15,0) -> 42090 | I4: =VLOOKUP(B4,[2]sales!$B$2:$G$183,6,0) -> Bulk | J4: Bulk | K4: YRFM | L4: =IF(H4>23335,0,(H4*90%*4.75%)) -> 0 | M4: =IF(H4*60%*12%>1800,1974,(H4*60%*13.16%)) -> 1974 | N4: =H4+L4+M4 -> 44064
A5: 4 | B5: 4553 | C5: Baburajan Parakkal | D5: =VLOOKUP(B5,[2]sales!$B$2:$D$183,3,0) -> Territory Sales Executive | E5: 22.12.2017 | F5: S1 | G5: =VLOOKUP(B5,[9]Staff!B$7:H$245,7,0) -> 17000 | H5: =VLOOKUP(B5,[9]Staff!B$7:P$245,15,0) -> 17000 | I5: =VLOOKUP(B5,[2]sales!$B$2:$G$183,6,0) -> Bulk | J5: Bulk | K5: YRFM | L5: =IF(H5>23335,0,(H5*90%*4.75%)) -> 726.75 | M5: =IF(H5*60%*12%>1800,1974,(H5*60%*13.16%)) -> 1342.32 | N5: =H5+L5+M5 -> 19069.07
A6: 5 | B6: 31 | C6: K Jayakumar | D6: =VLOOKUP(B6,[2]sales!$B$2:$D$183,3,0) -> Area Sales Manager | E6: 02.06.2000 | F6: M1 | G6: =VLOOKUP(B6,[9]Staff!B$7:H$245,7,0) -> 44490 | H6: =VLOOKUP(B6,[9]Staff!B$7:P$245,15,0) -> 44490 | I6: =VLOOKUP(B6,[2]sales!$B$2:$G$183,6,0) -> Tamilnadu | J6: Tamil Nadu | K6: YRFM | L6: =IF(H6>23335,0,(H6*90%*4.75%)) -> 0 | M6: =IF(H6*60%*12%>1800,1974,(H6*60%*13.16%)) -> 1974 | N6: =H6+L6+M6 -> 46464
A7: 6 | B7: 4528 | C7: P.Balamurugan | D7: =VLOOKUP(B7,[2]sales!$B$2:$D$183,3,0) -> Territory Sales Executive | E7: 06.12.2017 | F7: S1 | G7: =VLOOKUP(B7,'[5]Hosur-Apr''18'!B$5:H$127,7,0) -> 16000 | H7: =VLOOKUP(B7,'[5]Hosur-Apr''18'!B$5:M$127,12,0) -> 16000 | I7: =VLOOKUP(B7,[2]sales!$B$2:$G$183,6,0) -> Tamilnadu | J7: Tamil Nadu | K7: Hosur | L7: =IF(H7>21000,0,(H7*4.75%)) -> 760 | M7: =IF(H7*70%*12%>1800,1974,(H7*70%*12%)) -> 1344 | N7: =H7+L7+M7 -> 18104
A8: 7 | B8: 4580 | C8: Karthikeyan.M | D8: =VLOOKUP(B8,[2]sales!$B$2:$D$183,3,0) -> Territory Sales Executive | E8: 01.02.2018 | F8: S1 | G8: =VLOOKUP(B8,'[5]Hosur-Apr''18'!B$5:H$127,7,0) -> 21100 | H8: =VLOOKUP(B8,'[5]Hosur-Apr''18'!B$5:M$127,12,0) -> 21100 | I8: =VLOOKUP(B8,[2]sales!$B$2:$G$183,6,0) -> Tamilnadu | J8: Tamil Nadu | K8: Hosur | L8: =IF(H8>21000,0,(H8*4.75%)) -> 0 | M8: =IF(H8*70%*12%>1800,1974,(H8*70%*12%)) -> 1772.4 | N8: =H8+L8+M8 -> 22872.4
A9: 8 | B9: 36 | C9: Sunil A V | D9: =VLOOKUP(B9,[2]sales!$B$2:$D$183,3,0) -> Territory Sales Executive | E9: 06.07.2004 | F9: S1 | G9: =VLOOKUP(B9,[9]Staff!B$7:H$245,7,0) -> 28690 | H9: =VLOOKUP(B9,[9]Staff!B$7:P$245,15,0) -> 28690 | I9: =VLOOKUP(B9,[2]sales!$B$2:$G$183,6,0) -> CPD North | J9: CPD | K9: YRFM | L9: =IF(H9>23335,0,(H9*90%*4.75%)) -> 0 | M9: =IF(H9*60%*12%>1800,1974,(H9*60%*13.16%)) -> 1974 | N9: =H9+L9+M9 -> 30664
A10: 9 | B10: 4583 | C10: Sujith.M | D10: =VLOOKUP(B10,[2]sales!$B$2:$D$183,3,0) -> Sr. Territory Sales Executive | E10: 05.02.18 | F10: S2 | G10: =VLOOKUP(B10,'[6]staff klmsy (2)'!$B$7:I$84,8,0) -> 25500 | H10: =VLOOKUP(B10,'[6]staff klmsy (2)'!B$7:R$84,17,0) -> 25500 | I10: =VLOOKUP(B10,[2]sales!$B$2:$G$183,6,0) -> CPD North | J10: CPD | K10: Kalamassery | L10: =IF(H10>23335,0,(H10*90%*4.75%)) -> 0 | M10: =IF(H10*60%*12%>1800,1974,(H10*60%*13.16%)) -> 1974 | N10: =H10+L10+M10 -> 27474
A11: 10 | B11: 259 | C11: Thomas Abraham | D11: =VLOOKUP(B11,[2]sales!$B$2:$D$183,3,0) -> Area Sales Manager | E11: 01.12.2004 | F11: M2 | G11: =VLOOKUP(B11,'[4]salary aroor'!B$7:H$52,7,0) -> 44400 | H11: =VLOOKUP(B11,'[4]salary aroor'!B$7:L$52,11,0) -> 44400 | I11: =VLOOKUP(B11,[2]sales!$B$2:$G$183,6,0) -> CPD South | J11: CPD | K11: Aroor | L11: =IF(H11>23335,0,(H11*90%*4.75%)) -> 0 | M11: =IF(H11*60%*12%>1800,1974,(H11*60%*13.16%)) -> 1974 | N11: =H11+L11+M11 -> 46374
A12: 11 | B12: 285 | C12: Santhosh Kumar | D12: =VLOOKUP(B12,[2]sales!$B$2:$D$183,3,0) -> Sr. Territory Sales Executive | E12: 01.04.2006 | F12: S2 | G12: =VLOOKUP(B12,'[4]salary aroor'!B$7:H$52,7,0) -> 29310 | H12: =VLOOKUP(B12,'[4]salary aroor'!B$7:L$52,11,0) -> 29310 | I12: =VLOOKUP(B12,[2]sales!$B$2:$G$183,6,0) -> Bakery South | J12: Bakery-South | K12: Aroor | L12: =IF(H12>23335,0,(H12*90%*4.75%)) -> 0 | M12: =IF(H12*60%*12%>1800,1974,(H12*60%*13.16%)) -> 1974 | N12: =H12+L12+M12 -> 31284
A13: 12 | B13: 555 | C13: Rajeev K L | D13: =VLOOKUP(B13,[2]sales!$B$2:$D$183,3,0) -> Sr. Territory Sales Executive | E13: 01.03.2001 | F13: P2 | G13: =VLOOKUP(B13,'[3]april (2)'!B$8:H$132,7,0) -> 29910 | H13: =VLOOKUP(B13,'[3]april (2)'!B$8:N$132,13,0) -> 29910 | I13: =VLOOKUP(B13,[2]sales!$B$2:$G$183,6,0) -> Institution Sales | J13: Agro Sales | K13: Agro | L13: =IF(H13>23335,0,(H13*90%*4.75%)) -> 0 | M13: =IF(H13*60%*12%>1800,1974,(H13*60%*13.16%)) -> 1974 | N13: =H13+L13+M13 -> 31884
A14: 13 | B14: 567 | C14: Manikandan T | D14: =VLOOKUP(B14,[2]sales!$B$2:$D$183,3,0) -> Area Sales Manager | E14: 14.03.2005 | F14: M1 | G14: =VLOOKUP(B14,'[3]april (2)'!B$8:H$132,7,0) -> 41300 | H14: =VLOOKUP(B14,'[3]april (2)'!B$8:N$132,13,0) -> 41300 | I14: =VLOOKUP(B14,[2]sales!$B$2:$G$183,6,0) -> Institution Sales | J14: Agro Sales | K14: Agro | L14: =IF(H14>23335,0,(H14*90%*4.75%)) -> 0 | M14: =IF(H14*60%*12%>1800,1974,(H14*60%*13.16%)) -> 1974 | N14: =H14+L14+M14 -> 43274
A15: 14 | B15: 731 | C15: K C Reghunath | D15: =VLOOKUP(B15,[2]sales!$B$2:$D$183,3,0) -> Sr. Territory Sales Executive | E15: 01.05.2008 | F15: S2 | G15: =VLOOKUP(B15,[9]Staff!B$7:H$245,7,0) -> 19780 | H15: =VLOOKUP(B15,[9]Staff!B$7:P$245,15,0) -> 19780 | I15: =VLOOKUP(B15,[2]sales!$B$2:$G$183,6,0) -> Bulk | J15: Bulk | K15: YRFM | L15: =IF(H15>23335,0,(H15*90%*4.75%)) -> 845.595 | M15: =IF(H15*60%*12%>1800,1974,(H15*60%*13.16%)) -> 1561.8288 | N15: =H15+L15+M15 -> 22187.424
A16: 15 | B16: 808 | C16: Sujesh K T | D16: =VLOOKUP(B16,[2]sales!$B$2:$D$183,3,0) -> Territory Sales Executive | E16: 01.10.2008 | F16: S1 | G16: =VLOOKUP(B16,[9]Staff!B$7:H$245,7,0) -> 19140 | H16: =VLOOKUP(B16,[9]Staff!B$7:P$245,15,0) -> 19140 | I16: =VLOOKUP(B16,[2]sales!$B$2:$G$183,6,0) -> Institution Sales | J16: Agro Sales | K16: YRFM | L16: =IF(H16>23335,0,(H16*90%*4.75%)) -> 818.235 | M16: =IF(H16*60%*12%>1800,1974,(H16*60%*13.16%)) -> 1511.2944 | N16: =H16+L16+M16 -> 21469.529
A17: 16 | B17: 904 | C17: Sunil Kumar K | D17: =VLOOKUP(B17,[2]sales!$B$2:$D$183,3,0) -> Territory Sales Manager | E17: 01.04.2008 | F17: P3 | G17: =VLOOKUP(B17,'[8]Tasty Toast-Apr''18'!B$5:H$61,7,0) -> 26990 | H17: =VLOOKUP(B17,'[8]Tasty Toast-Apr''18'!B$5:N$61,13,0) -> 26990 | I17: =VLOOKUP(B17,[2]sales!$B$2:$G$183,6,0) -> Bakery South | J17: Bakery-South | K17: Breads | L17: =IF(H17>21000,0,(H17*4.75%)) -> 0 | M17: =IF(H17*70%*12%>1800,1974,(H17*70%*12%)) -> 1974 | N17: =H17+L17+M17 -> 28964
A18: 17 | B18: 1056 | C18: K M Girish Kumar | D18: =VLOOKUP(B18,[2]sales!$B$2:$D$183,3,0) -> Sr. Territory Sales Executive | E18: 22.12.2008 | F18: S2 | G18: =VLOOKUP(B18,[9]Staff!B$7:H$245,7,0) -> 19020 | H18: =VLOOKUP(B18,[9]Staff!B$7:P$245,15,0) -> 19020 | I18: =VLOOKUP(B18,[2]sales!$B$2:$G$183,6,0) -> Bulk | J18: Bulk | K18: YRFM | L18: =IF(H18>23335,0,(H18*90%*4.75%)) -> 813.105 | M18: =IF(H18*60%*12%>1800,1974,(H18*60%*13.16%)) -> 1501.8192 | N18: =H18+L18+M18 -> 21334.924
A19: 18 | B19: 1210 | C19: Govind S Menon | D19: Sales Coordinator | E19: 25.06.2008 | F19: M1 | G19: =VLOOKUP(B19,'[6]staff klmsy (2)'!$B$7:I$84,8,0) -> 38120 | H19: =VLOOKUP(B19,'[6]staff klmsy (2)'!B$7:R$84,17,0) -> 38120 | I19: Bulk | J19: Bulk | K19: Kalamassery | L19: =IF(H19>23335,0,(H19*90%*4.75%)) -> 0 | M19: =IF(H19*60%*12%>1800,1974,(H19*60%*13.16%)) -> 1974 | N19: =H19+L19+M19 -> 40094
A20: 19 | B20: 1213 | C20: Rajeesh .P | D20: =VLOOKUP(B20,[2]sales!$B$2:$D$183,3,0) -> Territory Sales Executive | E20: 01.11.2008 | F20: S2 | G20: =VLOOKUP(B20,'[6]staff klmsy (2)'!$B$7:I$84,8,0) -> 17450 | H20: =VLOOKUP(B20,'[6]staff klmsy (2)'!B$7:R$84,17,0) -> 17450 | I20: =VLOOKUP(B20,[2]sales!$B$2:$G$183,6,0) -> Bakery North | J20: Bakery-North | K20: Kalamassery | L20: =IF(H20>23335,0,(H20*90%*4.75%)) -> 745.9875 | M20: =IF(H20*60%*12%>1800,1974,(H20*60%*13.16%)) -> 1377.852 | N20: =H20+L20+M20 -> 19573.839
A21: 20 | B21: 1221 | C21: Abbas.B | D21: =VLOOKUP(B21,[2]sales!$B$2:$D$183,3,0) -> Territory Sales Executive | E21: 12.06.2009 | F21: S2 | G21: =VLOOKUP(B21,'[6]staff klmsy (2)'!$B$7:I$84,8,0) -> 25030 | H21: =VLOOKUP(B21,'[6]staff klmsy (2)'!B$7:R$84,17,0) -> 25030 | I21: =VLOOKUP(B21,[2]sales!$B$2:$G$183,6,0) -> Bakery South | J21: Bakery-South | K21: Kalamassery | L21: =IF(H21>23335,0,(H21*90%*4.75%)) -> 0 | M21: =IF(H21*60%*12%>1800,1974,(H21*60%*13.16%)) -> 1974 | N21: =H21+L21+M21 -> 27004
A22: 21 | B22: 1256 | C22: Unnikrishnan M | D22: Mechandiser | E22: 28.09.2009 | F22: F2 | G22: =VLOOKUP(B22,[9]Staff!B$7:H$245,7,0) -> 14840 | H22: =VLOOKUP(B22,[9]Staff!B$7:P$245,15,0) -> 14840 | I22: Institutional Sales | J22: Institutional Sales | K22: YRFM | L22: =IF(H22>23335,0,(H22*90%*4.75%)) -> 634.41 | M22: =IF(H22*60%*12%>1800,1974,(H22*60%*13.16%)) -> 1171.7664 | N22: =H22+L22+M22 -> 16646.176
A23: 22 | B23: 1276 | C23: Gopinathan K | D23: =VLOOKUP(B23,[2]sales!$B$2:$D$183,3,0) -> Territory Sales Executive | E23: 07.09.2009 | F23: S2 | G23: =VLOOKUP(B23,'[8]Tasty Toast-Apr''18'!B$5:H$61,7,0) -> 20650 | H23: =VLOOKUP(B23,'[8]Tasty Toast-Apr''18'!B$5:N$61,13,0) -> 20650 | I23: =VLOOKUP(B23,[2]sales!$B$2:$G$183,6,0) -> Bakery North | J23: CPD | K23: Breads | L23: =IF(H23>21000,0,(H23*4.75%)) -> 980.875 | M23: =IF(H23*70%*12%>1800,1974,(H23*70%*12%)) -> 1734.6 | N23: =H23+L23+M23 -> 23365.475
A24: 23 | B24: 4554 | C24: R.Suriyan | D24: =VLOOKUP(B24,[2]sales!$B$2:$D$183,3,0) -> Territory Sales Executive | E24: 06.01.2018 | F24: S1 | G24: =VLOOKUP(B24,'[5]Hosur-Apr''18'!B$5:H$127,7,0) -> 12500 | H24: =VLOOKUP(B24,'[5]Hosur-Apr''18'!B$5:M$127,12,0) -> 12500 | I24: =VLOOKUP(B24,[2]sales!$B$2:$G$183,6,0) -> Tamilnadu | K24: Hosur | L24: =IF(H24>21000,0,(H24*4.75%)) -> 593.75 | M24: =IF(H24*70%*12%>1800,1974,(H24*70%*12%)) -> 1050 | N24: =H24+L24+M24 -> 14143.75
A25: 24 | B25: 1397 | C25: Jayakumar K P | D25: =VLOOKUP(B25,[2]sales!$B$2:$D$183,3,0) -> Territory Sales Executive | E25: 01.09.2010 | F25: S1 | G25: =VLOOKUP(B25,[9]Staff!B$7:H$245,7,0) -> 15070 | H25: =VLOOKUP(B25,[9]Staff!B$7:P$245,15,0) -> 15070 | I25: =VLOOKUP(B25,[2]sales!$B$2:$G$183,6,0) -> Bulk | J25: Bulk | K25: YRFM | L25: =IF(H25>23335,0,(H25*90%*4.75%)) -> 644.2425 | M25: =IF(H25*60%*12%>1800,1974,(H25*60%*13.16%)) -> 1189.9272 | N25: =H25+L25+M25 -> 16904.17
A26: 25 | B26: 1420 | C26: Prasanth V B | D26: =VLOOKUP(B26,[2]sales!$B$2:$D$183,3,0) -> Sr. Territory Sales Executive | E26: 10.03.2010 | F26: S2 | G26: =VLOOKUP(B26,[9]Staff!B$7:H$245,7,0) -> 22090 | H26: =VLOOKUP(B26,[9]Staff!B$7:P$245,15,0) -> 22090 | I26: =VLOOKUP(B26,[2]sales!$B$2:$G$183,6,0) -> CPD North | J26: CPD | K26: YRFM | L26: =IF(H26>23335,0,(H26*90%*4.75%)) -> 944.3475 | M26: =IF(H26*60%*12%>1800,1974,(H26*60%*13.16%)) -> 1744.2264 | N26: =H26+L26+M26 -> 24778.574
A27: 26 | B27: 1423 | C27: Kalesh Kumar | D27: =VLOOKUP(B27,[2]sales!$B$2:$D$183,3,0) -> Territory Sales Executive | E27: 20.11.2009 | F27: S2 | G27: =VLOOKUP(B27,'[6]staff klmsy (2)'!$B$7:I$84,8,0) -> 21190 | H27: =VLOOKUP(B27,'[6]staff klmsy (2)'!B$7:R$84,17,0) -> 9888.67 | I27: =VLOOKUP(B27,[2]sales!$B$2:$G$183,6,0) -> Bakery South | J27: Bakery-South | K27: Kalamassery | L27: =IF(H27>23335,0,(H27*90%*4.75%)) -> 422.74064 | M27: =IF(H27*60%*12%>1800,1974,(H27*60%*13.16%)) -> 780.80938 | N27: =H27+L27+M27 -> 11092.22
A28: 27 | B28: 1450 | C28: S Mohan Kumar | D28: =VLOOKUP(B28,[2]sales!$B$2:$D$183,3,0) -> Territory Sales Executive | E28: 01.04.2010 | F28: S1 | G28: =VLOOKUP(B28,[9]Staff!B$7:H$245,7,0) -> 17720 | H28: =VLOOKUP(B28,[9]Staff!B$7:P$245,15,0) -> 17720 | I28: =VLOOKUP(B28,[2]sales!$B$2:$G$183,6,0) -> CPD South | J28: CPD | K28: YRFM | L28: =IF(H28>23335,0,(H28*90%*4.75%)) -> 757.53 | M28: =IF(H28*60%*12%>1800,1974,(H28*60%*13.16%)) -> 1399.1712 | N28: =H28+L28+M28 -> 19876.701
A29: 28 | B29: 1467 | C29: Selvan R | D29: =VLOOKUP(B29,[2]sales!$B$2:$D$183,3,0) -> Territory Sales Manager | E29: 12.04.2010 | F29: P3 | G29: =VLOOKUP(B29,'[4]salary aroor'!B$7:H$52,7,0) -> 29100 | H29: =VLOOKUP(B29,'[4]salary aroor'!B$7:L$52,11,0) -> 29100 | I29: Snacks | J29: Bread & Cakes | K29: Aroor | L29: =IF(H29>23335,0,(H29*90%*4.75%)) -> 0 | M29: =IF(H29*60%*12%>1800,1974,(H29*60%*13.16%)) -> 1974 | N29: =H29+L29+M29 -> 31074
A30: 29 | B30: 4960 | C30: Anu.E.J | D30: Sales Representative | E30: 10.04.2018 | F30: F2 | G30: =VLOOKUP(B30,'[4]salary aroor'!B$7:H$52,7,0) -> 12500 | H30: =VLOOKUP(B30,'[4]salary aroor'!B$7:L$52,11,0) -> 9875 | I30: Snacks | K30: Aroor | L30: =IF(H30>23335,0,(H30*90%*4.75%)) -> 422.15625 | M30: =IF(H30*60%*12%>1800,1974,(H30*60%*13.16%)) -> 779.73 | N30: =H30+L30+M30 -> 11076.886
A31: 30 | B31: 4961 | C31: Vipin Kumar.V | D31: Sales Representative | E31: 10.04.2018 | F31: F2 | G31: =VLOOKUP(B31,'[4]salary aroor'!B$7:H$52,7,0) -> 13000 | H31: =VLOOKUP(B31,'[4]salary aroor'!B$7:L$52,11,0) -> 10270 | I31: Snacks | K31: Aroor | L31: =IF(H31>23335,0,(H31*90%*4.75%)) -> 439.0425 | M31: =IF(H31*60%*12%>1800,1974,(H31*60%*13.16%)) -> 810.9192 | N31: =H31+L31+M31 -> 11519.962
A32: 31 | B32: 1525 | C32: Navaneeth Krishnan | D32: =VLOOKUP(B32,[2]sales!$B$2:$D$183,3,0) -> Sr. Territory Sales Executive | E32: 16.06.2010 | F32: S2 | G32: =VLOOKUP(B32,[9]Staff!B$7:H$245,7,0) -> 21630 | H32: =VLOOKUP(B32,[9]Staff!B$7:P$245,15,0) -> 21630 | I32: =VLOOKUP(B32,[2]sales!$B$2:$G$183,6,0) -> Modern Trade | J32: Modern Trade | K32: YRFM | L32: =IF(H32>23335,0,(H32*90%*4.75%)) -> 924.6825 | M32: =IF(H32*60%*12%>1800,1974,(H32*60%*13.16%)) -> 1707.9048 | N32: =H32+L32+M32 -> 24262.587
A33: 32 | B33: 1526 | C33: Sunil Kumar N.P. | D33: Merchandiser | E33: 14.06.2010 | F33: F2 | G33: =VLOOKUP(B33,'[8]Tasty Toast-Apr''18'!B$5:H$61,7,0) -> 21830 | H33: =VLOOKUP(B33,'[8]Tasty Toast-Apr''18'!B$5:N$61,13,0) -> 21830 | I33: North Kerala Bakery | J33: Bread & Cakes | K33: Breads | L33: =IF(H33>21000,0,(H33*4.75%)) -> 0 | M33: =IF(H33*70%*12%>1800,1974,(H33*70%*12%)) -> 1974 | N33: =H33+L33+M33 -> 23804
A34: 33 | B34: 1546 | C34: Sudheer Babu P. | D34: =VLOOKUP(B34,[2]sales!$B$2:$D$183,3,0) -> Territory Sales Executive | E34: 28.06.2010 | F34: S1 | G34: =VLOOKUP(B34,'[8]Tasty Toast-Apr''18'!B$5:H$61,7,0) -> 21180 | H34: =VLOOKUP(B34,'[8]Tasty Toast-Apr''18'!B$5:N$61,13,0) -> 21180 | I34: =VLOOKUP(B34,[2]sales!$B$2:$G$183,6,0) -> Modern Trade | J34: Modern Trade | K34: Breads | L34: =IF(H34>21000,0,(H34*4.75%)) -> 0 | M34: =IF(H34*70%*12%>1800,1974,(H34*70%*12%)) -> 1779.12 | N34: =H34+L34+M34 -> 22959.12
A35: 34 | B35: 1617 | C35: Sreelal R | D35: =VLOOKUP(B35,[2]sales!$B$2:$D$183,3,0) -> Sr. Territory Sales Executive | E35: 01.02.2011 | F35: S2 | G35: =VLOOKUP(B35,[9]Staff!B$7:H$245,7,0) -> 23440 | H35: =VLOOKUP(B35,[9]Staff!B$7:P$245,15,0) -> 23440 | I35: =VLOOKUP(B35,[2]sales!$B$2:$G$183,6,0) -> Modern Trade | J35: Modern Trade | K35: YRFM | L35: =IF(H35>23335,0,(H35*90%*4.75%)) -> 0 | M35: =IF(H35*60%*12%>1800,1974,(H35*60%*13.16%)) -> 1850.8224 | N35: =H35+L35+M35 -> 25290.822
A36: 35 | B36: 1676 | C36: Suresh Kumar | D36: =VLOOKUP(B36,[2]sales!$B$2:$D$183,3,0) -> Territory Sales Manager | E36: 06.10.2010 | F36: P3 | G36: =VLOOKUP(B36,'[6]staff klmsy (2)'!$B$7:I$84,8,0) -> 32800 | H36: =VLOOKUP(B36,'[6]staff klmsy (2)'!B$7:R$84,17,0) -> 32800 | I36: =VLOOKUP(B36,[2]sales!$B$2:$G$183,6,0) -> Bakery South | J36: Bread & Cakes | K36: Kalamassery | L36: =IF(H36>23335,0,(H36*90%*4.75%)) -> 0 | M36: =IF(H36*60%*12%>1800,1974,(H36*60%*13.16%)) -> 1974 | N36: =H36+L36+M36 -> 34774
A37: 36 | B37: 1682 | C37: Dinesh K G | D37: =VLOOKUP(B37,[2]sales!$B$2:$D$183,3,0) -> Regional Sales Manager | E37: 25.10.2010 | F37: SM1 | G37: =VLOOKUP(B37,[9]Staff!B$7:H$245,7,0) -> 131880 | H37: =VLOOKUP(B37,[9]Staff!B$7:P$245,15,0) -> 131880 | I37: =VLOOKUP(B37,[2]sales!$B$2:$G$183,6,0) -> Karnataka | J37: Karnataka | K37: YRFM | L37: =IF(H37>23335,0,(H37*90%*4.75%)) -> 0 | M37: =IF(H37*60%*12%>1800,1974,(H37*60%*13.16%)) -> 1974 | N37: =H37+L37+M37 -> 133854
A38: 37 | B38: 1747 | C38: Riyas S | D38: =VLOOKUP(B38,[2]sales!$B$2:$D$183,3,0) -> Territory Sales Executive | E38: 06.12.2010 | F38: S1 | G38: =VLOOKUP(B38,[9]Staff!B$7:H$245,7,0) -> 21680 | H38: =VLOOKUP(B38,[9]Staff!B$7:P$245,15,0) -> 21680 | I38: =VLOOKUP(B38,[2]sales!$B$2:$G$183,6,0) -> Bulk | J38: CPD | K38: YRFM | L38: =IF(H38>23335,0,(H38*90%*4.75%)) -> 926.82 | M38: =IF(H38*60%*12%>1800,1974,(H38*60%*13.16%)) -> 1711.8528 | N38: =H38+L38+M38 -> 24318.673
A39: 38 | B39: 4575 | C39: P.Naresh | D39: =VLOOKUP(B39,[2]sales!$B$2:$D$183,3,0) -> Sr. Territory Sales Executive | E39: 29.01.2018 | F39: S2 | G39: =VLOOKUP(B39,'[5]Hosur-Apr''18'!B$5:H$127,7,0) -> 30000 | H39: =VLOOKUP(B39,'[5]Hosur-Apr''18'!B$5:M$127,12,0) -> 30000 | I39: =VLOOKUP(B39,[2]sales!$B$2:$G$183,6,0) -> AP | J39: Karnataka | K39: Hosur | L39: =IF(H39>21000,0,(H39*4.75%)) -> 0 | M39: =IF(H39*70%*12%>1800,1974,(H39*70%*12%)) -> 1974 | N39: =H39+L39+M39 -> 31974
A40: 39 | B40: 4576 | C40: T.Amit Singh | D40: =VLOOKUP(B40,[2]sales!$B$2:$D$183,3,0) -> Territory Sales Executive | E40: 24.01.2018 | F40: S1 | G40: =VLOOKUP(B40,'[5]Hosur-Apr''18'!B$5:H$127,7,0) -> 21001 | H40: =VLOOKUP(B40,'[5]Hosur-Apr''18'!B$5:M$127,12,0) -> 21001 | I40: =VLOOKUP(B40,[2]sales!$B$2:$G$183,6,0) -> AP | J40: Karnataka | K40: Hosur | L40: =IF(H40>21000,0,(H40*4.75%)) -> 0 | M40: =IF(H40*70%*12%>1800,1974,(H40*70%*12%)) -> 1764.084 | N40: =H40+L40+M40 -> 22765.084
...

Sheet Quota
A1: Emp.No | B1: Quota
A2: 6 | B2: 12
A3: 10 | B3: 12
A4: 11 | B4: 12
A5: 16 | B5: 12
A6: 17 | B6: 12
A7: 18 | B7: 12
A8: 19 | B8: 12
A9: 20 | B9: 12
A10: 5264 | B10: 12
A11: 55 | B11: 12
A12: 57 | B12: 12
A13: 61 | B13: 12
... A310: 6492 | B310: 12
A311: 2721 | B311: 12
A312: 3613 | B312: 12
A313: 3615 | B313: 12
A314: 5458 | B314: 12
A315: 5906 | B315: 12
A316: 5914 | B316: 12
A317: 5922 | B317: 12
A318: 5942 | B318: 12
A319: 5977 | B319: 12
A320: 6039 | B320: 12
A321: 6146 | B321: 12
A322: 6197 | B322: 12
A323: 6205 | B323: 12
A324: 6264 | B324: 12
A325: 6350 | B325: 12
... A522: 5489 | B522: 12
A523: 1335 | B523: 12
A524: 4552 | B524: 12
A525: 4949 | B525: 12
A526: 5211 | B526: 12
A527: 5400 | B527: 12
A528: 5598 | B528: 12
A529: 5698 | B529: 12
A530: 5784 | B530: 12
A531: 5785 | B531: 12
A532: 5801 | B532: 12
...
